## Promise.reject()

`Promise.reject(reason)`方法也会返回一个新的Promise实例,该实例的状态为`rejected`

```
const p = Promise.reject('出错了')
//等同于
const p = new Promise((resolve,reject)=>{
  reject('出错了')
})

p.then(null,s=>console.log(s))
// 出错了
```

上面代码生成一个Promise对象的实例`p`,状态为`rejected`,回调函数会立即执行.

注意,`Promise.reject`方法的参数,会原封不动地作为`reject`的理由,变成后续方法的参数.这一点与`Promise.resolve`方法不一致.

```
const thenable = {
  then(resolve,reject){
    reject ('出错了')
  }
}
Promise.reject(thenable).catch(
  e=>console.log(e === thenable)
)
// true
```

上面代码中,`Promise.reject`方法的参数是一个`thenable`对象,执行以后,后面`catch`方法的参数不是`reject`抛出的"出错了"字符串,而是`thenable`对象.