## Promise.prototype.catch()

`Promise.prototype.catch`方法是`.then(null,rejection)`或`.then(undefined,rejection)`的别名,用于指定发生错误时的回调函数

```
getJSON('/posts.json').then(
  posts =>{
    // ...
  }
).catch(
  error => console.log('错误',error)
)
```

上面代码中,`getJSON`方法返回一个Promise对象,如果该对象状态变为`resolved`,则会调用`then`方法指定的回调函数;如果异步操作抛出错误,状态就会变为`rejected`,就会调用`catch`方法指定的回调函数,处理这个错误.另外,`then`方法指定的回调函数,如果运行中抛出错误,也会被`catch`方法捕获.

```
p.then((val) => console.log('fulfilled:', val))
  .catch((err) => console.log('rejected', err))

// 等同于
p.then((val) => console.log('fulfilled:', val))
  .then(null, (err) => console.log("rejected:", err))
```

下面一个例子

```
const promise = new Promise(
  (resolve,reject) => throw new Error('test')
)

promise.catch(
  error => console.log(error)
)
// Error: test
```

上面代码中,`promise`抛出一个错误,就被`catch`方法指定的回调函数捕获.注意,上面的写法和下面两种写法是等价的.
```
// 写法一
const promise = new Promise(function(resolve, reject) {
  try {
    throw new Error('test');
  } catch(e) {
    reject(e);
  }
});
promise.catch(function(error) {
  console.log(error);
});

// 写法二
const promise = new Promise(function(resolve, reject) {
  reject(new Error('test'));
});
promise.catch(function(error) {
  console.log(error);
});
```

比较上面两种写法,可以发现`reject`方法的作用,等同于抛出错误

如果Promise状态已经变成`resolved`,再抛出错误是无效的
```
const promise = new Promise(
  (resolve,reject) =>{
    resolve('ok')
    throw new Error('test')
  }
)
pormise.then(
  value => console.log(value)
).catch(
  error => console.log(error)
)
//  ok
```

上面代码中,Promise在`resolve`语句后面,再抛出错误,不会被捕获,等于没有抛出.因这Promise的状态一旦改变,就永久保重该状态,不会再变了.

Promise对象的错误具有冒泡性质,会一直向后传递,走到被捕获为止.也就是说,错误总是会被下一个`catch`语句捕获.

```
getJSON('/post/1.json').then(
  post => return getJSON(post.commentURL)
).then(
  cpmments =>{
    // some code
  }
).catch(
  error => {
    // 处理须三个Promise产生的错误
  }
)
```

上面代码中,一共有三个Promise对象,一个由`getJSON`产生,两个由`then`产生.它们之中任何一个抛出的错误,都会被最后一个`catch`捕获.

一般来说,不要在`then`方法里面定义`reject`状态的回调函数(即`then`的第二个参数),总是使用`catch`方法.

```
// bad
promise
  .then(function(data) {
    // success
  }, function(err) {
    // error
  });

// good
promise
  .then(function(data) { //cb
    // success
  })
  .catch(function(err) {
    // error
  });
```

上面代码中,第二种写法要好于第一种写法,理由是第二种写法可以捕获前面`then`方法执行中的错误,也更接近同步的写法,因此,建议总是使用`catch`方法,而不使用`then`方法的第二个参数.

跟你传统的`try/catch`代码块不同的是,如果没有使用`catch`方法指定错误处理的回调函数,Promise对象抛出的错误不会传递到外层代码,即不会有任何反应.

```
const someAsyncThing = () => {
  return new Promise(
    (resolve,reject) =>{
      //下面一行会报错,因为x没有声明
      resolve(x + 2)
    }
  )
}

someAsyncThing().then(() => {
  console.log('everything is great')
})

setTimeout(() => {
  console.log(123)
},20000)

// 报错:x 未定义
// 123
```

上面代码中,`someAsyncThing`函数产生 rPromise对象,内部有语法错误.浏览器运行到这一行,会打印出错误提示`ReferenceError: x is not defined`,但是不会退出进程,终止脚本执行,2秒之后还会输出`123`.这就是说,Promise内部的错误不会影响到Promise外部的代码

```
Promise.resolve().catch(
  err => console.log('错误: ',err)
).then(
  () => console.log('carry on')
)
// carry on
```

上面的代码因为没有报错,路过了`catch`方法,直接执行后面的`then`方法,此时,要是`then`方法里面报错,就与前面的`catch`无关了.

`catch`就去之中,还能再抛出错误

```
const someAsyncThing = function() {
  return new Promise(function(resolve, reject) {
    // 下面一行会报错，因为x没有声明
    resolve(x + 2);
  });
};

someAsyncThing().then(function() {
  console.log('everything is great');
});

setTimeout(() => { console.log(123) }, 2000); 
```

上面代码中,`catch`方法抛出一个错误,因为后面没有别的`catch`方法了,陆臻这个错误不会被捕获,也不会传递到外层.

```
const someAsyncThing = function() {
  return new Promise(function(resolve, reject) {
    // 下面一行会报错，因为x没有声明
    resolve(x + 2);
  });
};

someAsyncThing().then(function() {
  console.log('everything is great');
});

setTimeout(() => { console.log(123) }, 2000);
```

上面代码中,第二个`catch`方法用来捕获前一个`catch`方法报出的错误.