## async函数的语法  
---
**返回Promise对象**

async函数内部return语句返回的值,会成为then方法回调函数的参数.
```
async function f(){
  return 'hello world'
}

f().then(v => console.log(v))
// hello world
```
上面代码中,函数f内部return命令返回的值,会被then方法回调函数接收到.

async函数内部抛出错误,会导致返回的Promise对象变为reject状态.抛出的错误对象会被catch方法回调函数接收到
```
async function f(){
  throw new Error('error')
}

f().then(
  v => console.log(v),
  e => console.log(e)
)
// Error:error
```

---
**Promise对象的状态变化**

async函数返回的Promise对象,必须等到内部所有await命令后面的Promise对象执行完,才会发生状态改变,除非遇到return语句或者抛出错误,也就是说,只有async函数内部的异步操作执行完,才执行then方法指定的回调函数.
```
async function getTitle(url){
  let response = await fetch(url)
  let html = await response.text()
  return html.match(/<title>([\s\S]+)<\/title>/i)[1]
}
getTitle('https://tc39.github.io/ecma262/).then(console.log)
//ECMAScript® 2020 Language&nbsp;Specification
```
上面代码中,函数getTitle内部有三个操作,抓取见面,取出文本,匹配文本,匹配页面标题.只有这三个操作全部完成,才会执行then方法里面的`console.log`

---
**await命令**

正常情况下,await命令后面是一个Promise对象,返回该对象的结果.如果不是Promise对象,就直接返回对应的值
```
async function f(){
  //等同于 return 123
  return await 123
}

f().then(v => console.log(v))
// 123 
```
上面代码中,await命令的参数是数值123,这里等同于return 123

另一种情况是,await命令后面是一个thenable对象(即定义then方法的对象),那么await会将其等同于Promise对象
```
class Sleeo{
  constructor(timeout){
    this.timeout = timeout
  }
  then(resolve,reject){
    const startTime = Date.now()
    setTimeout(
      () => resolve(Date.now() - startTime),
      this.timeout
    )
  }
}

(async () => {
  const actualTime = await new Sleep(1000)
  console.log(actualTime)
})()
```
上面代码中await命令后面是一个Sleep对象的实例,这全实例不是promise对象,但是因为定义了then方法,await对将会视为Promise处理

await命令后面的Promise对象如果变为reject状态,则reject参数会被catch方法的回调函数接收到

```
async function f(){
  await Promise.reject('error')
}
f()
.then(v => console.log(v))
.catch(e => console.log(e))
//error
```
上面代码中,await语句没有return,但是reject方法的参数依然传入catch方法的回调函数.这里如果在await前面加上return,效果是一样的

任何一个await语句后面的Promise对象变为reject状态,那么整个async函数都会中断执行

```
async function f(){
  await Promise.reject('error')
  await Promise resolve('hello wotld')  //并不会执行
}
```
上面代码中,第二个await语句是不会执行的,因为第一个await语句状态变成了reject

有时,我们希望即使前一个异步操作失败,也不要中断后面的异步操作.这时可以将第一个await放在`try...catch`结构里面,这样不管这个异步操作是否成功,第二个await都会执行
```
async function f(){
  try{
    await Promise.reject('error')
  } catch(e) {}
  return await promise.resolve('hello world')
}

f()
.then(v => console.log(v))
//hello world
```
另一种方法是await后面的Promise对象再跟一个catch处理前面可能出现的错误
```
async function f(){
  await Promise.reject('error')
    .catch(e => console.log(e))
  return await Promise.resolve('hello,world')
}

f()
.then(v => consoe.log(v))
// error
// hello world
```

---
**错误处理**

如果await后面的异步操作出错,那么等同于async函数返回的Promise对象被reject
```
async function f() {
  await new Promise(function (resolve, reject) {
    throw new Error('出错了')
  })
}

f()
.then(v => console.log(v))
.catch(e => console.log(e))
```
上面代码中,async函数f执行后,await后面的Promise对象会抛出一个错误对象导致catch方法的回调函数被调用,它的参数就是抛出错误对象.

防止出错的方法,也是将其放在`try...catch`代码块之中
```
async function f(){
  try{
    await new Promise((resolve,reject) => {
      throw new Error('error')
    })
  }catch(e){}
  return await('hello world')
}
```
如果有多个await命令,可以给我一下放在`try...catch`结构中
```
async function main(){
  try{
    const val1 = await firstStep()
    const val2 = await secondStep(val1)
    const val3 = await thirdStep(val1,val2)

    console.log('Final',val3)
  } catch(err){
    console.error(err)
  }
}
```
下面例子使用`try...catch`结构,实现多次重复尝试
```
const superagent = require('superagent')
const NUM_RETRIES = 3

asyc function test(){
  let i
  for(i = 0;i < NUM_RETRIES; ++i){
    try{
      await superagent.get('http://google.com/this-throws-an-error')
      break
    }catch(err){}
  }
  console.log(i)    // 3
}
test()
```
上面代码中,如果await操作成功,就会使用break语句退出循环,如果失败,会被catch语句捕捉,然后进入下一轮循环.

---
**使用注意点**

第一点,前面已经说过,await命令后面的Promise对象,运行结果可以有是rejected,所以最好把await命令放在`try...catch`代码块中
```
async function myFunction(){
  try{
    await somethingReturnsAPromise()
  }catch(err)(
    consoe.log(err)
  )
}
//另一种写法
async function myFunction(){
  await somethingThatReturnsAPromise()
  .catch(err => {
    console.log(err)
  })
}
```
第二点,多个await命令后面的异步操作,如果不存在继发关系,最好让它们同时触发.
```
//写法一
let [foo,bar] = await Promise.all([getFoo(),getBar()])

//写法二
let fooPromise = getFoo()
let barPromise = getBar()
let foo = await fooPromise
let bar = await barPromise
```
上面两种写法,getFoo和getBar都是同时触发,这样就会缩短程序的执行时间

第三点,await命令只能用在async函数中,如果用在普通函数,就会报错
```
async function dbFuc(db){
  let doccs = [{},{},{}]

  //报错
  docs.forEach(doc => {
    await db.posst(doc)
  })
}
```
上面代码会报错,是因为await彡在普通函数之中了,但是如果将forEach方法的参数改成async函数,也有问题
```
function dbFuc(db){ //这里不需要async
  let docs = [{},{},{}]

  //可能得到错误结果
  docs.forEach(async function(doc){
    await db.post(doc)
  })
}
```
上面代码可能不会正常工作,原因是这时三个db.post操作是并发进行的,也就是同时执行,而不是继发执行,正确的写法是用for循环
```
async function dbFuc(db){
  let docs = [{},{},{}]

  for(let doc of docs){
    await db.post(doc)
  }
}
```
如果确实希望多个请求并发执行,可以wget Promise.all方法.当三个请求都会resolved时,下面两种写法效果相同
```
async function dbFuc(db){
  let docs = [{}{},{}]
  let promises = docs.map(doc => {
    db.post(doc)
  })

  let results = await = await Promise.all(promises)
  console.log(result)
}

//或使用下面的写法

async function dbFuc(db){
  let docs = [{}{},{}]
  let promises = doc/map(doc => {
    db.post(doc)
  }) 

  let result = []
  for(let promise of promises){
    result.push(await promise)
  }
  console.log(results)
}
```
目前,ems模块加载器支持顶层await,即await命令可以不放在async函数里面直接使用.
```
//async 函数的写法
const start = async () => {
  const res = await fetch('google.com')
  return res.text()
}

start().then(console.log)

//顶层await方法写法
const res = await fetch('google.com')
console.log(await res.text())
```
上面代码中,第二种写法的脚本必须使用esm加载器,才会生效

第四点,async函数可以保留运行堆栈
```
const a = () => {
  b().then(() => {
    c()
  })
}
```
上面代码中,函数a内部运行了一个异步任务b().当b()运行的时候,函数a()不会中断,而是继续运行,等到b()运行结束,可能a()早就运行结束了,b()所在的一下文环境已经消失了.如果b()或c()报错,错误堆栈将不包括a()

现在将这个例子改成async函数
```
const a = async () => {
  await b()
  c()
}
```
上面代码中,b()运行的时候,a()是暂停执行,上下文环境都保存着.一旦b()或c()报错,错误堆栈包括a()